<?xml version="1.0" encoding="utf-8"?>
<!-- This URDF was automatically created by SolidWorks to URDF Exporter! Originally created by Stephen Brawner (brawner@gmail.com) 
     Commit Version: 1.6.0-4-g7f85cfe  Build Version: 1.6.7995.38578
     For more information, please see http://wiki.ros.org/sw_urdf_exporter -->
<robot
  name="project_hot">
  <link
    name="base_link">
    <inertial>
      <origin
        xyz="-0.000151101059932132 -2.93020815944622E-14 0.0360808042551358"
        rpy="0 0 0" />
      <mass
        value="1.59590770123768" />
      <inertia
        ixx="0.00982941426976709"
        ixy="1.64069015580728E-08"
        ixz="3.2195771218049E-06"
        iyy="0.0370814414687927"
        iyz="-5.8207267696326E-09"
        izz="0.0435919405103592" />
    </inertial>
    <visual>
      <origin
        xyz="0 0 0"
        rpy="0 0 0" />
      <geometry>
        <mesh
          filename="package://project_hot/meshes/base_link.STL" />
      </geometry>
      <material
        name="">
        <color
          rgba="0.792156862745098 0.819607843137255 0.933333333333333 1" />
      </material>
    </visual>
    <collision>
      <origin
        xyz="0 0 0"
        rpy="0 0 0" />
      <geometry>
        <mesh
          filename="package://project_hot/meshes/base_link.STL" />
      </geometry>
    </collision>
  </link>
  <link
    name="FR_hip_leg">
    <inertial>
      <origin
        xyz="-0.0493860304905318 0.0861267751640668 0.0297190531044023"
        rpy="0 0 0" />
      <mass
        value="0.204569331769132" />
      <inertia
        ixx="0.000482950622079233"
        ixy="0.000107962716611928"
        ixz="2.57287580253101E-07"
        iyy="0.00025203362976228"
        iyz="8.42604188111788E-07"
        izz="0.000401214203111183" />
    </inertial>
    <visual>
      <origin
        xyz="0 0 0"
        rpy="0 0 0" />
      <geometry>
        <mesh
          filename="package://project_hot/meshes/FR_hip_leg.STL" />
      </geometry>
      <material
        name="">
        <color
          rgba="0.792156862745098 0.819607843137255 0.933333333333333 1" />
      </material>
    </visual>
    <collision>
      <origin
        xyz="0 0 0"
        rpy="0 0 0" />
      <geometry>
        <mesh
          filename="package://project_hot/meshes/FR_hip_leg.STL" />
      </geometry>
    </collision>
  </link>
  <joint
    name="FR_HIP_LEG"
    type="continuous">
    <origin
      xyz="0.21 -0.1773 0.04"
      rpy="-1.5707963267949 0 0" />
    <parent
      link="base_link" />
    <child
      link="FR_hip_leg" />
    <axis
      xyz="0 0 -1" />
    <limit
      effort="10"
      velocity="10" />
  </joint>
  <link
    name="FR_knee_leg">
    <inertial>
      <origin
        xyz="0.00774806636439732 0.0525324435623831 0.0271041858191073"
        rpy="0 0 0" />
      <mass
        value="0.0563034898702062" />
      <inertia
        ixx="8.30189739916403E-05"
        ixy="-3.53219989059757E-06"
        ixz="-2.01378002180236E-09"
        iyy="3.7406829364892E-05"
        iyz="1.08663878536901E-08"
        izz="5.42431190915607E-05" />
    </inertial>
    <visual>
      <origin
        xyz="0 0 0"
        rpy="0 0 0" />
      <geometry>
        <mesh
          filename="package://project_hot/meshes/FR_knee_leg.STL" />
      </geometry>
      <material
        name="">
        <color
          rgba="0.792156862745098 0.819607843137255 0.933333333333333 1" />
      </material>
    </visual>
    <collision>
      <origin
        xyz="0 0 0"
        rpy="0 0 0" />
      <geometry>
        <mesh
          filename="package://project_hot/meshes/FR_knee_leg.STL" />
      </geometry>
    </collision>
  </link>
  <joint
    name="FR_KNEE_LEG"
    type="continuous">
    <origin
      xyz="-0.0520792704962449 0.139457143470731 0.0028499999999998"
      rpy="0 0 0" />
    <parent
      link="FR_hip_leg" />
    <child
      link="FR_knee_leg" />
    <axis
      xyz="0 0 1" />
    <limit
      effort="10"
      velocity="10" />
  </joint>
  <link
    name="FR_leg_foot">
    <inertial>
      <origin
        xyz="0.00788055469414789 0.0422750947440941 0.0232238169253756"
        rpy="0 0 0" />
      <mass
        value="0.0671982080720275" />
      <inertia
        ixx="2.78841987322554E-05"
        ixy="6.34195240661471E-07"
        ixz="-2.57748820834425E-08"
        iyy="3.02330679109391E-05"
        iyz="-1.01961561325197E-07"
        izz="1.12702108291899E-05" />
    </inertial>
    <visual>
      <origin
        xyz="0 0 0"
        rpy="0 0 0" />
      <geometry>
        <mesh
          filename="package://project_hot/meshes/FR_leg_foot.STL" />
      </geometry>
      <material
        name="">
        <color
          rgba="0.792156862745098 0.819607843137255 0.933333333333333 1" />
      </material>
    </visual>
    <collision>
      <origin
        xyz="0 0 0"
        rpy="0 0 0" />
      <geometry>
        <mesh
          filename="package://project_hot/meshes/FR_leg_foot.STL" />
      </geometry>
    </collision>
  </link>
  <joint
    name="FR_LEG_foot"
    type="continuous">
    <origin
      xyz="-0.028488 0.10631 0.0057"
      rpy="0 0 0" />
    <parent
      link="FR_knee_leg" />
    <child
      link="FR_leg_foot" />
    <axis
      xyz="0 0 1" />
    <limit
      effort="10"
      velocity="10" />
  </joint>
  <link
    name="FR_leg_steering">
    <inertial>
      <origin
        xyz="-0.00452122434708185 -0.0231588908093107 0.0229677930997373"
        rpy="0 0 0" />
      <mass
        value="0.0345233816728568" />
      <inertia
        ixx="2.60023361479333E-05"
        ixy="-2.11400866429808E-06"
        ixz="9.58577209534931E-07"
        iyy="1.76805628406605E-05"
        iyz="7.55308480057754E-06"
        izz="1.71851985200097E-05" />
    </inertial>
    <visual>
      <origin
        xyz="0 0 0"
        rpy="0 0 0" />
      <geometry>
        <mesh
          filename="package://project_hot/meshes/FR_leg_steering.STL" />
      </geometry>
      <material
        name="">
        <color
          rgba="0.792156862745098 0.819607843137255 0.933333333333333 1" />
      </material>
    </visual>
    <collision>
      <origin
        xyz="0 0 0"
        rpy="0 0 0" />
      <geometry>
        <mesh
          filename="package://project_hot/meshes/FR_leg_steering.STL" />
      </geometry>
    </collision>
  </link>
  <joint
    name="FR_LEG_STEERING"
    type="continuous">
    <origin
      xyz="0.012595 0.061231 0.011595"
      rpy="-1.5708 0 0" />
    <parent
      link="FR_leg_foot" />
    <child
      link="FR_leg_steering" />
    <axis
      xyz="0.2451 0 0.9695" />
    <limit
      effort="10"
      velocity="10" />
  </joint>
  <link
    name="RF_leg_wheel">
    <inertial>
      <origin
        xyz="-0.00269658626678712 0.000777332640689965 0.00655736324161921"
        rpy="0 0 0" />
      <mass
        value="0.0625586708019178" />
      <inertia
        ixx="0.000109150756010706"
        ixy="-2.86285551062966E-06"
        ixz="-2.74274000454464E-05"
        iyy="9.82801878630719E-05"
        iyz="6.84269099706079E-06"
        izz="0.000162867185630762" />
    </inertial>
    <visual>
      <origin
        xyz="0 0 0"
        rpy="0 0 0" />
      <geometry>
        <mesh
          filename="package://project_hot/meshes/RF_leg_wheel.STL" />
      </geometry>
      <material
        name="">
        <color
          rgba="0.298039215686275 0.298039215686275 0.298039215686275 1" />
      </material>
    </visual>
    <collision>
      <origin
        xyz="0 0 0"
        rpy="0 0 0" />
      <geometry>
        <mesh
          filename="package://project_hot/meshes/RF_leg_wheel.STL" />
      </geometry>
    </collision>
  </link>
  <joint
    name="LEG_LEG_WHEEL"
    type="continuous">
    <origin
      xyz="0.021197 0.0062409 0.072826"
      rpy="1.5708 0 0" />
    <parent
      link="FR_leg_steering" />
    <child
      link="RF_leg_wheel" />
    <axis
      xyz="0.38499 -0.09733 -0.91778" />
    <limit
      effort="10"
      velocity="10" />
    <dynamics
      damping="0.1"
      friction="0.1" />
  </joint>
  <link
    name="FL_hip_leg">
    <inertial>
      <origin
        xyz="-0.0646593434558959 0.0784000912505611 -0.0310771142466191"
        rpy="0 0 0" />
      <mass
        value="0.21473624759" />
      <inertia
        ixx="0.000446305762859324"
        ixy="0.000139531366976782"
        ixz="1.13288093012706E-07"
        iyy="0.000296326771972987"
        iyz="8.73696075807206E-07"
        izz="0.000404255883333166" />
    </inertial>
    <visual>
      <origin
        xyz="0 0 0"
        rpy="0 0 0" />
      <geometry>
        <mesh
          filename="package://project_hot/meshes/FL_hip_leg.STL" />
      </geometry>
      <material
        name="">
        <color
          rgba="0.792156862745098 0.819607843137255 0.933333333333333 1" />
      </material>
    </visual>
    <collision>
      <origin
        xyz="0 0 0"
        rpy="0 0 0" />
      <geometry>
        <mesh
          filename="package://project_hot/meshes/FL_hip_leg.STL" />
      </geometry>
    </collision>
  </link>
  <joint
    name="FL_HIP_LEH"
    type="continuous">
    <origin
      xyz="0.21 0.1785 0.0399999999999999"
      rpy="-1.5707963267949 0 0" />
    <parent
      link="base_link" />
    <child
      link="FL_hip_leg" />
    <axis
      xyz="0 0 1" />
    <limit
      effort="10"
      velocity="10" />
  </joint>
  <link
    name="FL_knee_leg">
    <inertial>
      <origin
        xyz="-0.00111365968227137 0.0530890966715402 -0.0261957971452797"
        rpy="0 0 0" />
      <mass
        value="0.0563034596335536" />
      <inertia
        ixx="8.29131505552523E-05"
        ixy="4.15795626758201E-06"
        ixz="-3.80951296044349E-09"
        iyy="3.75125478044291E-05"
        iyz="1.04213232024258E-08"
        izz="5.42430627920472E-05" />
    </inertial>
    <visual>
      <origin
        xyz="0 0 0"
        rpy="0 0 0" />
      <geometry>
        <mesh
          filename="package://project_hot/meshes/FL_knee_leg.STL" />
      </geometry>
      <material
        name="">
        <color
          rgba="0.843137254901961 0.811764705882353 0 1" />
      </material>
    </visual>
    <collision>
      <origin
        xyz="0 0 0"
        rpy="0 0 0" />
      <geometry>
        <mesh
          filename="package://project_hot/meshes/FL_knee_leg.STL" />
      </geometry>
    </collision>
  </link>
  <joint
    name="FL_KNEE_LEG"
    type="continuous">
    <origin
      xyz="-0.0745887183049647 0.12882960988088 -0.00465000000000027"
      rpy="0 0 0" />
    <parent
      link="FL_hip_leg" />
    <child
      link="FL_knee_leg" />
    <axis
      xyz="0 0 1" />
    <limit
      effort="10"
      velocity="10" />
  </joint>
  <link
    name="FL_foot_leg">
    <inertial>
      <origin
        xyz="0.00342438905056888 0.0452959073382621 -0.0147876552645599"
        rpy="0 0 0" />
      <mass
        value="0.0544202009223978" />
      <inertia
        ixx="2.21498703575316E-05"
        ixy="9.994138502757E-08"
        ixz="-7.12185325767339E-09"
        iyy="2.33870260753267E-05"
        iyz="-8.85925948200142E-08"
        izz="9.38934977795975E-06" />
    </inertial>
    <visual>
      <origin
        xyz="0 0 0"
        rpy="0 0 0" />
      <geometry>
        <mesh
          filename="package://project_hot/meshes/FL_foot_leg.STL" />
      </geometry>
      <material
        name="">
        <color
          rgba="0.792156862745098 0.819607843137255 0.933333333333333 1" />
      </material>
    </visual>
    <collision>
      <origin
        xyz="0 0 0"
        rpy="0 0 0" />
      <geometry>
        <mesh
          filename="package://project_hot/meshes/FL_foot_leg.STL" />
      </geometry>
    </collision>
  </link>
  <joint
    name="FL_FOOT_LEG"
    type="continuous">
    <origin
      xyz="-0.0483417979478693 0.10027767921474 -0.0097000000000024"
      rpy="0 0 0" />
    <parent
      link="FL_knee_leg" />
    <child
      link="FL_foot_leg" />
    <axis
      xyz="0 0 -1" />
    <limit
      effort="10"
      velocity="10" />
  </joint>
  <link
    name="FL_steering">
    <inertial>
      <origin
        xyz="-0.00828511368940257 -0.0231588876139516 0.0218933312991373"
        rpy="0 0 0" />
      <mass
        value="0.0345233833008326" />
      <inertia
        ixx="2.54425380095312E-05"
        ixy="-3.34301610425066E-06"
        ixz="2.35399962061661E-06"
        iyy="1.76805638140081E-05"
        iyz="7.09523492193558E-06"
        izz="1.77449961495055E-05" />
    </inertial>
    <visual>
      <origin
        xyz="0 0 0"
        rpy="0 0 0" />
      <geometry>
        <mesh
          filename="package://project_hot/meshes/FL_steering.STL" />
      </geometry>
      <material
        name="">
        <color
          rgba="0.792156862745098 0.819607843137255 0.933333333333333 1" />
      </material>
    </visual>
    <collision>
      <origin
        xyz="0 0 0"
        rpy="0 0 0" />
      <geometry>
        <mesh
          filename="package://project_hot/meshes/FL_steering.STL" />
      </geometry>
    </collision>
  </link>
  <joint
    name="FL_STEERING"
    type="continuous">
    <origin
      xyz="0.0047549 0.062269 -0.026305"
      rpy="-1.5708 0 0" />
    <parent
      link="FL_foot_leg" />
    <child
      link="FL_steering" />
    <axis
      xyz="0.08013 0 0.99678" />
    <limit
      effort="10"
      velocity="10" />
    <dynamics
      damping="0.1"
      friction="0.1" />
  </joint>
  <link
    name="FL_wheel">
    <inertial>
      <origin
        xyz="-0.00239245001997127 0.000285391644588073 0.00563963313880322"
        rpy="0 0 0" />
      <mass
        value="0.0625585572564107" />
      <inertia
        ixx="0.000109789737162551"
        ixy="-9.1781325087378E-07"
        ixz="-2.81840623133954E-05"
        iyy="9.76408597706116E-05"
        iyz="2.17682592396524E-06"
        izz="0.000162866837404322" />
    </inertial>
    <visual>
      <origin
        xyz="0 0 0"
        rpy="0 0 0" />
      <geometry>
        <mesh
          filename="package://project_hot/meshes/FL_wheel.STL" />
      </geometry>
      <material
        name="">
        <color
          rgba="0.298039215686275 0.298039215686275 0.298039215686275 1" />
      </material>
    </visual>
    <collision>
      <origin
        xyz="0 0 0"
        rpy="0 0 0" />
      <geometry>
        <mesh
          filename="package://project_hot/meshes/FL_wheel.STL" />
      </geometry>
    </collision>
  </link>
  <joint
    name="FL_WHEEL"
    type="continuous">
    <origin
      xyz="0.0083696 0.0053231 0.075372"
      rpy="1.5708 0 0" />
    <parent
      link="FL_steering" />
    <child
      link="FL_wheel" />
    <axis
      xyz="0.39582 -0.03182 -0.91778" />
    <limit
      effort="10"
      velocity="10" />
    <dynamics
      damping="0.1"
      friction="0.1" />
  </joint>
  <link
    name="BL_hip_leg">
    <inertial>
      <origin
        xyz="0.062765044428237 0.0799246773369 -0.0249028856845379"
        rpy="0 0 0" />
      <mass
        value="0.214736250036533" />
      <inertia
        ixx="0.000452894815673893"
        ixy="-0.000135784271560711"
        ixz="1.34159440135606E-07"
        iyy="0.000289737728022034"
        iyz="-8.70735927010169E-07"
        izz="0.000404255892580987" />
    </inertial>
    <visual>
      <origin
        xyz="0 0 0"
        rpy="0 0 0" />
      <geometry>
        <mesh
          filename="package://project_hot/meshes/BL_hip_leg.STL" />
      </geometry>
      <material
        name="">
        <color
          rgba="0.792156862745098 0.819607843137255 0.933333333333333 1" />
      </material>
    </visual>
    <collision>
      <origin
        xyz="0 0 0"
        rpy="0 0 0" />
      <geometry>
        <mesh
          filename="package://project_hot/meshes/BL_hip_leg.STL" />
      </geometry>
    </collision>
  </link>
  <joint
    name="BL_HIP_LEG"
    type="continuous">
    <origin
      xyz="-0.21 0.17248 0.04"
      rpy="-1.5707963267949 0 0" />
    <parent
      link="base_link" />
    <child
      link="BL_hip_leg" />
    <axis
      xyz="0 0 1" />
    <limit
      effort="10"
      velocity="10" />
  </joint>
  <link
    name="BL_knee_leg">
    <inertial>
      <origin
        xyz="-0.000156860422974775 0.0531005474575022 -0.0271042052196531"
        rpy="0 0 0" />
      <mass
        value="0.0563034557204064" />
      <inertia
        ixx="8.30860596034438E-05"
        ixy="-3.06725688793152E-06"
        ixz="-3.56102382272015E-09"
        iyy="3.73396245333874E-05"
        iyz="-1.05155673908825E-08"
        izz="5.4243055045816E-05" />
    </inertial>
    <visual>
      <origin
        xyz="0 0 0"
        rpy="0 0 0" />
      <geometry>
        <mesh
          filename="package://project_hot/meshes/BL_knee_leg.STL" />
      </geometry>
      <material
        name="">
        <color
          rgba="0.843137254901961 0.811764705882353 0 1" />
      </material>
    </visual>
    <collision>
      <origin
        xyz="0 0 0"
        rpy="0 0 0" />
      <geometry>
        <mesh
          filename="package://project_hot/meshes/BL_knee_leg.STL" />
      </geometry>
    </collision>
  </link>
  <joint
    name="BL_KNEE_LEG"
    type="continuous">
    <origin
      xyz="0.0714850077060553 0.130577329401785 0.00197000000000019"
      rpy="0 0 0" />
    <parent
      link="BL_hip_leg" />
    <child
      link="BL_knee_leg" />
    <axis
      xyz="0 0 -1" />
    <limit
      effort="10"
      velocity="10" />
  </joint>
  <link
    name="BL_foot_leg">
    <inertial>
      <origin
        xyz="-0.00428736684183682 0.0427027985270238 -0.0201238165833599"
        rpy="0 0 0" />
      <mass
        value="0.0671982083804068" />
      <inertia
        ixx="2.77527218888534E-05"
        ixy="-2.758495599939E-07"
        ixz="-1.09325894204219E-08"
        iyy="3.03645460418635E-05"
        iyz="1.04599126523847E-07"
        izz="1.12702101756263E-05" />
    </inertial>
    <visual>
      <origin
        xyz="0 0 0"
        rpy="0 0 0" />
      <geometry>
        <mesh
          filename="package://project_hot/meshes/BL_foot_leg.STL" />
      </geometry>
      <material
        name="">
        <color
          rgba="0.792156862745098 0.819607843137255 0.933333333333333 1" />
      </material>
    </visual>
    <collision>
      <origin
        xyz="0 0 0"
        rpy="0 0 0" />
      <geometry>
        <mesh
          filename="package://project_hot/meshes/BL_foot_leg.STL" />
      </geometry>
    </collision>
  </link>
  <joint
    name="BL_FOOT_LEG"
    type="continuous">
    <origin
      xyz="0.0459287302457042 0.101405592131521 -0.00879999999999759"
      rpy="0 0 0" />
    <parent
      link="BL_knee_leg" />
    <child
      link="BL_foot_leg" />
    <axis
      xyz="0 0 -1" />
    <limit
      effort="10"
      velocity="10" />
  </joint>
  <link
    name="BL_steering">
    <inertial>
      <origin
        xyz="0.00775892385563995 0.0231588880745645 0.0220852925811976"
        rpy="0 0 0" />
      <mass
        value="0.0345233828273817" />
      <inertia
        ixx="2.55507425164469E-05"
        ixy="-3.17229910277934E-06"
        ixz="-2.16718611806498E-06"
        iyy="1.76805635272028E-05"
        iyz="-7.1731885609558E-06"
        izz="1.76367915264641E-05" />
    </inertial>
    <visual>
      <origin
        xyz="0 0 0"
        rpy="0 0 0" />
      <geometry>
        <mesh
          filename="package://project_hot/meshes/BL_steering.STL" />
      </geometry>
      <material
        name="">
        <color
          rgba="0.792156862745098 0.819607843137255 0.933333333333333 1" />
      </material>
    </visual>
    <collision>
      <origin
        xyz="0 0 0"
        rpy="0 0 0" />
      <geometry>
        <mesh
          filename="package://project_hot/meshes/BL_steering.STL" />
      </geometry>
    </collision>
  </link>
  <joint
    name="BL_STEERING"
    type="continuous">
    <origin
      xyz="-0.00624342492395817 0.0621376266461711 -0.00849480890112134"
      rpy="-1.5707963267949 0 0" />
    <parent
      link="BL_foot_leg" />
    <child
      link="BL_steering" />
    <axis
      xyz="-0.103956291283057 0 0.994581866666929" />
    <limit
      effort="10"
      velocity="10" />
  </joint>
  <link
    name="BL_wheel">
    <inertial>
      <origin
        xyz="0.00277998215256635 0.000383824149325585 -0.00655737096558764"
        rpy="0 0 0" />
      <mass
        value="0.0625586869225041" />
      <inertia
        ixx="0.000109738980189452"
        ixy="1.20732176541389E-06"
        ixz="-2.81239872620089E-05"
        iyy="9.76920610482077E-05"
        iyz="-2.85055175663538E-06"
        izz="0.000162867307523841" />
    </inertial>
    <visual>
      <origin
        xyz="0 0 0"
        rpy="0 0 0" />
      <geometry>
        <mesh
          filename="package://project_hot/meshes/BL_wheel.STL" />
      </geometry>
      <material
        name="">
        <color
          rgba="0.298039215686275 0.298039215686275 0.298039215686275 1" />
      </material>
    </visual>
    <collision>
      <origin
        xyz="0 0 0"
        rpy="0 0 0" />
      <geometry>
        <mesh
          filename="package://project_hot/meshes/BL_wheel.STL" />
      </geometry>
    </collision>
  </link>
  <joint
    name="BL_WHEEL"
    type="continuous">
    <origin
      xyz="-0.0105655325054485 -0.00624087406384091 0.0751085948064218"
      rpy="1.5707963267949 0 0" />
    <parent
      link="BL_steering" />
    <child
      link="BL_wheel" />
    <axis
      xyz="-0.394947886205581 -0.0412809833721077 0.917775597623719" />
    <limit
      effort="10"
      velocity="10" />
    <dynamics
      damping="0.1"
      friction="0.1" />
  </joint>
  <link
    name="BR_hip_leg">
    <inertial>
      <origin
        xyz="0.0672255390146745 0.0758695218363479 0.0312005017254162"
        rpy="0 0 0" />
      <mass
        value="0.213527468138879" />
      <inertia
        ixx="0.000436565265012075"
        ixy="-0.000144311752970515"
        ixz="8.34721955426952E-08"
        iyy="0.000305927686387191"
        iyz="-8.77046471642213E-07"
        izz="0.00040411791481062" />
    </inertial>
    <visual>
      <origin
        xyz="0 0 0"
        rpy="0 0 0" />
      <geometry>
        <mesh
          filename="package://project_hot/meshes/BR_hip_leg.STL" />
      </geometry>
      <material
        name="">
        <color
          rgba="0.792156862745098 0.819607843137255 0.933333333333333 1" />
      </material>
    </visual>
    <collision>
      <origin
        xyz="0 0 0"
        rpy="0 0 0" />
      <geometry>
        <mesh
          filename="package://project_hot/meshes/BR_hip_leg.STL" />
      </geometry>
    </collision>
  </link>
  <joint
    name="BR_HIP_LEG"
    type="continuous">
    <origin
      xyz="-0.21 -0.1785 0.0399999999999999"
      rpy="-1.5707963267949 0 0" />
    <parent
      link="base_link" />
    <child
      link="BR_hip_leg" />
    <axis
      xyz="0 0 -1" />
    <limit
      effort="10"
      velocity="10" />
  </joint>
  <link
    name="BR_knee_leg">
    <inertial>
      <origin
        xyz="0.00292074234177973 0.0530203918194807 0.0261957925655642"
        rpy="0 0 0" />
      <mass
        value="0.0563034482164378" />
      <inertia
        ixx="8.25774973136247E-05"
        ixy="-5.69334621501427E-06"
        ixz="-4.16059867942183E-09"
        iyy="3.78481794720687E-05"
        iyz="-1.02898932615508E-08"
        izz="5.42430568899995E-05" />
    </inertial>
    <visual>
      <origin
        xyz="0 0 0"
        rpy="0 0 0" />
      <geometry>
        <mesh
          filename="package://project_hot/meshes/BR_knee_leg.STL" />
      </geometry>
      <material
        name="">
        <color
          rgba="0.843137254901961 0.811764705882353 0 1" />
      </material>
    </visual>
    <collision>
      <origin
        xyz="0 0 0"
        rpy="0 0 0" />
      <geometry>
        <mesh
          filename="package://project_hot/meshes/BR_knee_leg.STL" />
      </geometry>
    </collision>
  </link>
  <joint
    name="BR_KNEE_LEG"
    type="continuous">
    <origin
      xyz="0.078932 0.12622 0.00465"
      rpy="0 0 0" />
    <parent
      link="BR_hip_leg" />
    <child
      link="BR_knee_leg" />
    <axis
      xyz="0 0 -1" />
    <limit
      effort="10"
      velocity="10" />
    <dynamics
      damping="0.1"
      friction="0.1" />
  </joint>
  <link
    name="BR_foot_leg">
    <inertial>
      <origin
        xyz="-0.00434916897724524 0.0427619934931083 0.0217761836428121"
        rpy="0 0 0" />
      <mass
        value="0.0671982086199827" />
      <inertia
        ixx="2.77295755811228E-05"
        ixy="-1.22887762142477E-07"
        ixz="-4.85311780476173E-09"
        iyy="3.03876932073729E-05"
        iyz="1.05056851820916E-07"
        izz="1.12702097282099E-05" />
    </inertial>
    <visual>
      <origin
        xyz="0 0 0"
        rpy="0 0 0" />
      <geometry>
        <mesh
          filename="package://project_hot/meshes/BR_foot_leg.STL" />
      </geometry>
      <material
        name="">
        <color
          rgba="0.792156862745098 0.819607843137255 0.933333333333333 1" />
      </material>
    </visual>
    <collision>
      <origin
        xyz="0 0 0"
        rpy="0 0 0" />
      <geometry>
        <mesh
          filename="package://project_hot/meshes/BR_foot_leg.STL" />
      </geometry>
    </collision>
  </link>
  <joint
    name="BR_FOOT_LEG"
    type="continuous">
    <origin
      xyz="0.0542720710637505 0.0986909502127203 0.00260000000000318"
      rpy="0 0 0" />
    <parent
      link="BR_knee_leg" />
    <child
      link="BR_foot_leg" />
    <axis
      xyz="0 0 1" />
    <limit
      effort="10"
      velocity="10" />
    <dynamics
      damping="0.1"
      friction="0.1" />
  </joint>
  <link
    name="BR_steering">
    <inertial>
      <origin
        xyz="0.00902579751170782 0.0215985200532103 -0.0231588869501209"
        rpy="0 0 0" />
      <mass
        value="0.0345233837660204" />
      <inertia
        ixx="2.52733941861471E-05"
        ixy="-2.61049790295428E-06"
        ixz="3.58267686864328E-06"
        iyy="1.79141401203281E-05"
        iyz="6.9772875424037E-06"
        izz="1.76805641870529E-05" />
    </inertial>
    <visual>
      <origin
        xyz="0 0 0"
        rpy="0 0 0" />
      <geometry>
        <mesh
          filename="package://project_hot/meshes/BR_steering.STL" />
      </geometry>
      <material
        name="">
        <color
          rgba="0.792156862745098 0.819607843137255 0.933333333333333 1" />
      </material>
    </visual>
    <collision>
      <origin
        xyz="0 0 0"
        rpy="0 0 0" />
      <geometry>
        <mesh
          filename="package://project_hot/meshes/BR_steering.STL" />
      </geometry>
    </collision>
  </link>
  <joint
    name="BR_STEERING"
    type="continuous">
    <origin
      xyz="-0.00517563172716813 0.0622775172308049 0.0334051910988779"
      rpy="0 0 0" />
    <parent
      link="BR_foot_leg" />
    <child
      link="BR_steering" />
    <axis
      xyz="-0.0461424930546299 0.998934867914172 0" />
    <limit
      effort="10"
      velocity="10" />
    <dynamics
      damping="0.1"
      friction="0.1" />
  </joint>
  <link
    name="BR_wheel">
    <inertial>
      <origin
        xyz="0.00279763250926485 0.000222103814460028 -0.00655737651559093"
        rpy="0 0 0" />
      <mass
        value="0.0625588340326886" />
      <inertia
        ixx="0.000109838271065952"
        ixy="5.02176269613149E-07"
        ixz="-2.82419649106995E-05"
        iyy="9.75930322394673E-05"
        iyz="-1.21590997244981E-06"
        izz="0.000162867432664728" />
    </inertial>
    <visual>
      <origin
        xyz="0 0 0"
        rpy="0 0 0" />
      <geometry>
        <mesh
          filename="package://project_hot/meshes/BR_wheel.STL" />
      </geometry>
      <material
        name="">
        <color
          rgba="0.298039215686275 0.298039215686275 0.298039215686275 1" />
      </material>
    </visual>
    <collision>
      <origin
        xyz="0 0 0"
        rpy="0 0 0" />
      <geometry>
        <mesh
          filename="package://project_hot/meshes/BR_wheel.STL" />
      </geometry>
    </collision>
  </link>
  <joint
    name="BR_WHEEL"
    type="continuous">
    <origin
      xyz="-0.00619500090488682 0.075594665517531 0.00624087406384094"
      rpy="0 0 0" />
    <parent
      link="BR_steering" />
    <child
      link="BR_wheel" />
    <axis
      xyz="-0.396676460492799 -0.018323157406152 0.917775597623719" />
    <limit
      effort="10"
      velocity="10" />
    <dynamics
      damping="0.1"
      friction="0.1" />
  </joint>
</robot>